{
  "cells": [
    {
      "cell_type": "markdown",
      "metadata": {
        "id": "view-in-github",
        "colab_type": "text"
      },
      "source": [
        "<a href=\"https://colab.research.google.com/github/luida-M/Modelo_ML/blob/main/Proyecto_ParteIII%2BMedina_Tenorio.ipynb\" target=\"_parent\"><img src=\"https://colab.research.google.com/assets/colab-badge.svg\" alt=\"Open In Colab\"/></a>"
      ]
    },
    {
      "cell_type": "code",
      "source": [
        "#from google.colab import drive\n",
        "#drive.mount('/content/drive', force_remount=True)\n",
        "# 1. Configuración Inicial\n",
        "from google.colab import drive\n",
        "import os\n",
        "drive.mount('/content/gdrive')\n",
        "# Establecer ruta de acceso en drive\n",
        "print(os.getcwd())\n",
        "os.chdir(\"/content/gdrive/My Drive\")\n",
        "\n",
        "import pandas as pd\n",
        "import numpy as np\n",
        "from matplotlib import pyplot as plt\n",
        "from sklearn.model_selection import train_test_split\n",
        "from sklearn.linear_model import LinearRegression, Ridge, Lasso, ElasticNet\n",
        "from sklearn.ensemble import RandomForestRegressor\n",
        "from sklearn.feature_selection import SelectKBest, f_regression\n",
        "from sklearn.metrics import mean_squared_error, r2_score\n",
        "import gspread\n",
        "from google.auth import default\n",
        "from google.colab import auth\n",
        "from sklearn.impute import SimpleImputer\n",
        "from google.colab import drive\n",
        "\n",
        "# Autenticación con Google\n",
        "auth.authenticate_user()\n",
        "creds, _ = default()\n",
        "gc = gspread.authorize(creds)\n",
        "\n",
        "# Configurar Git\n",
        "!git config --global user.email \"luidamedina@gmail.com\"\n",
        "!git config --global user.name \"Luida Medina\"\n",
        "\n",
        "# Clonar el repositorio\n",
        "!git clone https://github.com/luida-M/Modelo_ML.git\n",
        "%cd Modelo_ML\n",
        "\n",
        "# 2. Carga de Datos\n",
        "file_name = 'ventas-totales-supermercados-2'  # Nombre del archivo de Google Sheets\n",
        "\n",
        "try:\n",
        "    # Abrir la hoja de cálculo por nombre\n",
        "    sheet = gc.open(file_name).sheet1\n",
        "    # Obtener todos los datos de la hoja como una lista de listas\n",
        "    data = sheet.get_all_values()\n",
        "    # Convertir la lista de listas a un DataFrame de Pandas\n",
        "    df = pd.DataFrame(data[1:], columns=data[0])\n",
        "    # Convertir todas las columnas numéricas a tipo de datos numérico\n",
        "    for col in df.columns:\n",
        "        df[col] = pd.to_numeric(df[col], errors='coerce')\n",
        "    # Manejar valores faltantes (opcional, dependiendo de tu estrategia)\n",
        "    df.fillna(df.mean(), inplace=True)\n",
        "except gspread.SpreadsheetNotFound:\n",
        "    print(f\"No se encontró el archivo '{file_name}' en Google Sheets. Asegúrate de que el nombre sea correcto.\")\n",
        "except Exception as e:\n",
        "    print(f\"Error al leer el archivo de Google Sheets: {e}\")\n",
        "\n",
        "if 'df' in locals():\n",
        "    print(df.head())\n",
        "\n",
        "    # 3. Método de Feature Selection: SelectKBest\n",
        "    features = ['indice_tiempo','ventas_precios_corrientes', 'ventas_precios_constantes', 'ventas_totales_canal_venta',\n",
        "                'salon_ventas', 'canales_on_line', 'ventas_totales_medio_pago', 'efectivo', 'tarjetas_debito',\n",
        "                'tarjetas_credito', 'otros_medios', 'ventas_totales_grupo_articulos', 'subtotal_ventas_alimentos_bebidas',\n",
        "                'bebidas', 'almacen', 'panaderia', 'lacteos', 'carnes', 'verduleria_fruteria',\n",
        "                'alimentos_preparados_rotiseria', 'articulos_limpieza_perfumeria', 'indumentaria_calzado_textiles_hogar',\n",
        "                'electronicos_articulos_hogar', 'otros']\n",
        "\n",
        "    X = df[features]\n",
        "    y = df['ventas_precios_corrientes']\n",
        "\n",
        "    # Manejar valores faltantes con SimpleImputer\n",
        "    imputer = SimpleImputer(strategy='mean')\n",
        "    X = imputer.fit_transform(X)\n",
        "\n",
        "    selector = SelectKBest(score_func=f_regression, k=10)\n",
        "    X_new = selector.fit_transform(X, y)\n",
        "    selected_features = [features[i] for i in selector.get_support(indices=True)]\n",
        "    print(f\"Selected Features: {', '.join(selected_features)}\")\n",
        "\n",
        "    # Visualización de las características seleccionadas\n",
        "    plt.figure(figsize=(10, 7))\n",
        "    plt.barh(selected_features, selector.scores_[selector.get_support()])\n",
        "    plt.xlabel('Puntuación de Selección')\n",
        "    plt.ylabel('Características')\n",
        "    plt.title('Puntuación de las Características Seleccionadas')\n",
        "    plt.show()\n",
        "\n",
        "    # 4. Dividir Datos en Entrenamiento y Prueba\n",
        "    X_train, X_test, y_train, y_test = train_test_split(X_new, y, test_size=0.3, random_state=42) # 70% train, 30% test\n",
        "\n",
        "    # 5. Algoritmos de Regresión\n",
        "    models = {\n",
        "        \"Linear Regression\": LinearRegression(),\n",
        "        \"Random Forest\": RandomForestRegressor(random_state=42),\n",
        "        \"Ridge Regression\": Ridge(),\n",
        "        \"Lasso Regression\": Lasso(),\n",
        "        \"ElasticNet Regression\": ElasticNet()\n",
        "    }\n",
        "\n",
        "    # 6. Entrenamiento y Evaluación\n",
        "    results = {}\n",
        "    for name, model in models.items():\n",
        "        model.fit(X_train, y_train)\n",
        "        y_pred = model.predict(X_test)\n",
        "\n",
        "        # Visualizar comparaciones reales vs. predicciones\n",
        "        plt.figure(figsize=(10, 7))\n",
        "        plt.scatter(y_test, y_pred, color='blue')\n",
        "        plt.plot([min(y_test), max(y_test)], [min(y_test), max(y_test)], color='red', linestyle='--', linewidth=2)\n",
        "        plt.title(f'Comparación de Valores Reales vs. Predichos: {name}')\n",
        "        plt.xlabel('Valores Reales')\n",
        "        plt.ylabel('Valores Predichos')\n",
        "        plt.show()\n",
        "\n",
        "        mse = mean_squared_error(y_test, y_pred)\n",
        "        r2 = r2_score(y_test, y_pred)\n",
        "        results[name] = {\"MSE\": mse, \"R2\": r2}\n",
        "        print(f\"{name} - Mean Squared Error: {mse}\")\n",
        "        print(f\"{name} - R^2 Score: {r2}\")\n",
        "\n",
        "    # Visualización de Resultados\n",
        "    mse_values = [results[name][\"MSE\"] for name in results]\n",
        "    r2_values = [results[name][\"R2\"] for name in results]\n",
        "\n",
        "    plt.figure(figsize=(14, 6))\n",
        "    plt.subplot(1, 2, 1)\n",
        "    plt.barh(list(results.keys()), mse_values, color='skyblue')\n",
        "    plt.xlabel('Mean Squared Error (MSE)')\n",
        "    plt.title('Comparación de MSE entre Algoritmos')\n",
        "\n",
        "    plt.subplot(1, 2, 2)\n",
        "    plt.barh(list(results.keys()), r2_values, color='lightgreen')\n",
        "    plt.xlabel('R^2 Score')\n",
        "    plt.title('Comparación de R^2 entre Algoritmos')\n",
        "\n",
        "    plt.tight_layout()\n",
        "    plt.show()\n",
        "\n",
        "    # 7. Generación de Conclusiones\n",
        "    mejores_resultados = sorted(results.items(), key=lambda x: x[1][\"MSE\"])[0]\n",
        "    mejor_algoritmo = mejores_resultados[0]\n",
        "    mejor_mse = mejores_resultados[1][\"MSE\"]\n",
        "    mejor_r2 = mejores_resultados[1][\"R2\"]\n",
        "\n",
        "    conclusiones = f\"\"\"\n",
        "    1. Las características seleccionadas para el modelo son: {', '.join(selected_features)}.\n",
        "    2. El mejor algoritmo de regresión fue {mejor_algoritmo}, con un error cuadrático medio (MSE) de {mejor_mse} y un R^2 Score de {mejor_r2}.\n",
        "    3. Las características seleccionadas han mostrado ser relevantes para predecir 'ventas_precios_corrientes'.\n",
        "    4. Se recomienda utilizar el algoritmo {mejor_algoritmo} para predicciones futuras, ya que presentó el mejor desempeño en términos de MSE y R^2 Score.\n",
        "    \"\"\"\n",
        "    print(conclusiones)\n",
        "else:\n",
        "    print(\"No se puede proceder con el análisis ya que el archivo no se cargó correctamente.\")\n",
        "\n",
        "    # Subir cambios a GitHub\n",
        "    !git add . !git commit -m \"Análisis de datos y comparación de varios algoritmos de regresión\"\n",
        "    !git push origin main\n",
        "\n"
      ],
      "metadata": {
        "colab": {
          "base_uri": "https://localhost:8080/"
        },
        "id": "W4zGM4q8GMWw",
        "outputId": "bf02cb2f-3d13-438c-cc6b-82a57d42e567"
      },
      "execution_count": null,
      "outputs": [
        {
          "output_type": "stream",
          "name": "stderr",
          "text": [
            "ERROR:root:Internal Python error in the inspect module.\n",
            "Below is the traceback from this internal error.\n",
            "\n",
            "ERROR:root:Internal Python error in the inspect module.\n",
            "Below is the traceback from this internal error.\n",
            "\n",
            "ERROR:root:Internal Python error in the inspect module.\n",
            "Below is the traceback from this internal error.\n",
            "\n"
          ]
        },
        {
          "output_type": "stream",
          "name": "stdout",
          "text": [
            "Mounted at /content/gdrive\n",
            "Traceback (most recent call last):\n",
            "  File \"/usr/local/lib/python3.10/dist-packages/IPython/core/interactiveshell.py\", line 3553, in run_code\n",
            "    exec(code_obj, self.user_global_ns, self.user_ns)\n",
            "  File \"<ipython-input-6-54a707d7230b>\", line 8, in <cell line: 8>\n",
            "    print(os.getcwd())\n",
            "OSError: [Errno 107] Transport endpoint is not connected\n",
            "\n",
            "During handling of the above exception, another exception occurred:\n",
            "\n",
            "Traceback (most recent call last):\n",
            "  File \"/usr/local/lib/python3.10/dist-packages/IPython/core/interactiveshell.py\", line 2099, in showtraceback\n",
            "    stb = value._render_traceback_()\n",
            "AttributeError: 'OSError' object has no attribute '_render_traceback_'\n",
            "\n",
            "During handling of the above exception, another exception occurred:\n",
            "\n",
            "Traceback (most recent call last):\n",
            "  File \"/usr/local/lib/python3.10/dist-packages/IPython/core/ultratb.py\", line 1101, in get_records\n",
            "    return _fixed_getinnerframes(etb, number_of_lines_of_context, tb_offset)\n",
            "  File \"/usr/local/lib/python3.10/dist-packages/IPython/core/ultratb.py\", line 248, in wrapped\n",
            "    return f(*args, **kwargs)\n",
            "  File \"/usr/local/lib/python3.10/dist-packages/IPython/core/ultratb.py\", line 281, in _fixed_getinnerframes\n",
            "    records = fix_frame_records_filenames(inspect.getinnerframes(etb, context))\n",
            "  File \"/usr/lib/python3.10/inspect.py\", line 1662, in getinnerframes\n",
            "    frameinfo = (tb.tb_frame,) + getframeinfo(tb, context)\n",
            "  File \"/usr/lib/python3.10/inspect.py\", line 1620, in getframeinfo\n",
            "    filename = getsourcefile(frame) or getfile(frame)\n",
            "  File \"/usr/lib/python3.10/inspect.py\", line 829, in getsourcefile\n",
            "    module = getmodule(object, filename)\n",
            "  File \"/usr/lib/python3.10/inspect.py\", line 861, in getmodule\n",
            "    file = getabsfile(object, _filename)\n",
            "  File \"/usr/lib/python3.10/inspect.py\", line 845, in getabsfile\n",
            "    return os.path.normcase(os.path.abspath(_filename))\n",
            "  File \"/usr/lib/python3.10/posixpath.py\", line 384, in abspath\n",
            "    cwd = os.getcwd()\n",
            "OSError: [Errno 107] Transport endpoint is not connected\n",
            "Traceback (most recent call last):\n",
            "  File \"/usr/local/lib/python3.10/dist-packages/IPython/core/interactiveshell.py\", line 3553, in run_code\n",
            "    exec(code_obj, self.user_global_ns, self.user_ns)\n",
            "  File \"<ipython-input-6-54a707d7230b>\", line 8, in <cell line: 8>\n",
            "    print(os.getcwd())\n",
            "OSError: [Errno 107] Transport endpoint is not connected\n",
            "\n",
            "During handling of the above exception, another exception occurred:\n",
            "\n",
            "Traceback (most recent call last):\n",
            "  File \"/usr/local/lib/python3.10/dist-packages/IPython/core/interactiveshell.py\", line 2099, in showtraceback\n",
            "    stb = value._render_traceback_()\n",
            "AttributeError: 'OSError' object has no attribute '_render_traceback_'\n",
            "\n",
            "During handling of the above exception, another exception occurred:\n",
            "\n",
            "Traceback (most recent call last):\n",
            "  File \"/usr/local/lib/python3.10/dist-packages/IPython/core/interactiveshell.py\", line 3473, in run_ast_nodes\n",
            "    if (await self.run_code(code, result,  async_=asy)):\n",
            "  File \"/usr/local/lib/python3.10/dist-packages/IPython/core/interactiveshell.py\", line 3575, in run_code\n",
            "    self.showtraceback(running_compiled_code=True)\n",
            "  File \"/usr/local/lib/python3.10/dist-packages/IPython/core/interactiveshell.py\", line 2101, in showtraceback\n",
            "    stb = self.InteractiveTB.structured_traceback(etype,\n",
            "  File \"/usr/local/lib/python3.10/dist-packages/IPython/core/ultratb.py\", line 1367, in structured_traceback\n",
            "    return FormattedTB.structured_traceback(\n",
            "  File \"/usr/local/lib/python3.10/dist-packages/IPython/core/ultratb.py\", line 1267, in structured_traceback\n",
            "    return VerboseTB.structured_traceback(\n",
            "  File \"/usr/local/lib/python3.10/dist-packages/IPython/core/ultratb.py\", line 1124, in structured_traceback\n",
            "    formatted_exception = self.format_exception_as_a_whole(etype, evalue, etb, number_of_lines_of_context,\n",
            "  File \"/usr/local/lib/python3.10/dist-packages/IPython/core/ultratb.py\", line 1082, in format_exception_as_a_whole\n",
            "    last_unique, recursion_repeat = find_recursion(orig_etype, evalue, records)\n",
            "  File \"/usr/local/lib/python3.10/dist-packages/IPython/core/ultratb.py\", line 382, in find_recursion\n",
            "    return len(records), 0\n",
            "TypeError: object of type 'NoneType' has no len()\n",
            "\n",
            "During handling of the above exception, another exception occurred:\n",
            "\n",
            "Traceback (most recent call last):\n",
            "  File \"/usr/local/lib/python3.10/dist-packages/IPython/core/interactiveshell.py\", line 2099, in showtraceback\n",
            "    stb = value._render_traceback_()\n",
            "AttributeError: 'TypeError' object has no attribute '_render_traceback_'\n",
            "\n",
            "During handling of the above exception, another exception occurred:\n",
            "\n",
            "Traceback (most recent call last):\n",
            "  File \"/usr/local/lib/python3.10/dist-packages/IPython/core/ultratb.py\", line 1101, in get_records\n",
            "    return _fixed_getinnerframes(etb, number_of_lines_of_context, tb_offset)\n",
            "  File \"/usr/local/lib/python3.10/dist-packages/IPython/core/ultratb.py\", line 248, in wrapped\n",
            "    return f(*args, **kwargs)\n",
            "  File \"/usr/local/lib/python3.10/dist-packages/IPython/core/ultratb.py\", line 281, in _fixed_getinnerframes\n",
            "    records = fix_frame_records_filenames(inspect.getinnerframes(etb, context))\n",
            "  File \"/usr/lib/python3.10/inspect.py\", line 1662, in getinnerframes\n",
            "    frameinfo = (tb.tb_frame,) + getframeinfo(tb, context)\n",
            "  File \"/usr/lib/python3.10/inspect.py\", line 1620, in getframeinfo\n",
            "    filename = getsourcefile(frame) or getfile(frame)\n",
            "  File \"/usr/lib/python3.10/inspect.py\", line 829, in getsourcefile\n",
            "    module = getmodule(object, filename)\n",
            "  File \"/usr/lib/python3.10/inspect.py\", line 861, in getmodule\n",
            "    file = getabsfile(object, _filename)\n",
            "  File \"/usr/lib/python3.10/inspect.py\", line 845, in getabsfile\n",
            "    return os.path.normcase(os.path.abspath(_filename))\n",
            "  File \"/usr/lib/python3.10/posixpath.py\", line 384, in abspath\n",
            "    cwd = os.getcwd()\n",
            "OSError: [Errno 107] Transport endpoint is not connected\n",
            "Traceback (most recent call last):\n",
            "  File \"/usr/local/lib/python3.10/dist-packages/IPython/core/interactiveshell.py\", line 3553, in run_code\n",
            "    exec(code_obj, self.user_global_ns, self.user_ns)\n",
            "  File \"<ipython-input-6-54a707d7230b>\", line 8, in <cell line: 8>\n",
            "    print(os.getcwd())\n",
            "OSError: [Errno 107] Transport endpoint is not connected\n",
            "\n",
            "During handling of the above exception, another exception occurred:\n",
            "\n",
            "Traceback (most recent call last):\n",
            "  File \"/usr/local/lib/python3.10/dist-packages/IPython/core/interactiveshell.py\", line 2099, in showtraceback\n",
            "    stb = value._render_traceback_()\n",
            "AttributeError: 'OSError' object has no attribute '_render_traceback_'\n",
            "\n",
            "During handling of the above exception, another exception occurred:\n",
            "\n",
            "Traceback (most recent call last):\n",
            "  File \"/usr/local/lib/python3.10/dist-packages/IPython/core/interactiveshell.py\", line 3473, in run_ast_nodes\n",
            "    if (await self.run_code(code, result,  async_=asy)):\n",
            "  File \"/usr/local/lib/python3.10/dist-packages/IPython/core/interactiveshell.py\", line 3575, in run_code\n",
            "    self.showtraceback(running_compiled_code=True)\n",
            "  File \"/usr/local/lib/python3.10/dist-packages/IPython/core/interactiveshell.py\", line 2101, in showtraceback\n",
            "    stb = self.InteractiveTB.structured_traceback(etype,\n",
            "  File \"/usr/local/lib/python3.10/dist-packages/IPython/core/ultratb.py\", line 1367, in structured_traceback\n",
            "    return FormattedTB.structured_traceback(\n",
            "  File \"/usr/local/lib/python3.10/dist-packages/IPython/core/ultratb.py\", line 1267, in structured_traceback\n",
            "    return VerboseTB.structured_traceback(\n",
            "  File \"/usr/local/lib/python3.10/dist-packages/IPython/core/ultratb.py\", line 1124, in structured_traceback\n",
            "    formatted_exception = self.format_exception_as_a_whole(etype, evalue, etb, number_of_lines_of_context,\n",
            "  File \"/usr/local/lib/python3.10/dist-packages/IPython/core/ultratb.py\", line 1082, in format_exception_as_a_whole\n",
            "    last_unique, recursion_repeat = find_recursion(orig_etype, evalue, records)\n",
            "  File \"/usr/local/lib/python3.10/dist-packages/IPython/core/ultratb.py\", line 382, in find_recursion\n",
            "    return len(records), 0\n",
            "TypeError: object of type 'NoneType' has no len()\n",
            "\n",
            "During handling of the above exception, another exception occurred:\n",
            "\n",
            "Traceback (most recent call last):\n",
            "  File \"/usr/local/lib/python3.10/dist-packages/IPython/core/interactiveshell.py\", line 2099, in showtraceback\n",
            "    stb = value._render_traceback_()\n",
            "AttributeError: 'TypeError' object has no attribute '_render_traceback_'\n",
            "\n",
            "During handling of the above exception, another exception occurred:\n",
            "\n",
            "Traceback (most recent call last):\n",
            "  File \"/usr/local/lib/python3.10/dist-packages/IPython/core/interactiveshell.py\", line 3030, in _run_cell\n",
            "    return runner(coro)\n",
            "  File \"/usr/local/lib/python3.10/dist-packages/IPython/core/async_helpers.py\", line 78, in _pseudo_sync_runner\n",
            "    coro.send(None)\n",
            "  File \"/usr/local/lib/python3.10/dist-packages/IPython/core/interactiveshell.py\", line 3257, in run_cell_async\n",
            "    has_raised = await self.run_ast_nodes(code_ast.body, cell_name,\n",
            "  File \"/usr/local/lib/python3.10/dist-packages/IPython/core/interactiveshell.py\", line 3492, in run_ast_nodes\n",
            "    self.showtraceback()\n",
            "  File \"/usr/local/lib/python3.10/dist-packages/IPython/core/interactiveshell.py\", line 2101, in showtraceback\n",
            "    stb = self.InteractiveTB.structured_traceback(etype,\n",
            "  File \"/usr/local/lib/python3.10/dist-packages/IPython/core/ultratb.py\", line 1367, in structured_traceback\n",
            "    return FormattedTB.structured_traceback(\n",
            "  File \"/usr/local/lib/python3.10/dist-packages/IPython/core/ultratb.py\", line 1267, in structured_traceback\n",
            "    return VerboseTB.structured_traceback(\n",
            "  File \"/usr/local/lib/python3.10/dist-packages/IPython/core/ultratb.py\", line 1142, in structured_traceback\n",
            "    formatted_exceptions += self.format_exception_as_a_whole(etype, evalue, etb, lines_of_context,\n",
            "  File \"/usr/local/lib/python3.10/dist-packages/IPython/core/ultratb.py\", line 1082, in format_exception_as_a_whole\n",
            "    last_unique, recursion_repeat = find_recursion(orig_etype, evalue, records)\n",
            "  File \"/usr/local/lib/python3.10/dist-packages/IPython/core/ultratb.py\", line 382, in find_recursion\n",
            "    return len(records), 0\n",
            "TypeError: object of type 'NoneType' has no len()\n",
            "\n",
            "During handling of the above exception, another exception occurred:\n",
            "\n",
            "Traceback (most recent call last):\n",
            "  File \"/usr/local/lib/python3.10/dist-packages/IPython/core/interactiveshell.py\", line 2099, in showtraceback\n",
            "    stb = value._render_traceback_()\n",
            "AttributeError: 'TypeError' object has no attribute '_render_traceback_'\n",
            "\n",
            "During handling of the above exception, another exception occurred:\n",
            "\n",
            "Traceback (most recent call last):\n",
            "  File \"/usr/local/lib/python3.10/dist-packages/IPython/core/ultratb.py\", line 1101, in get_records\n",
            "    return _fixed_getinnerframes(etb, number_of_lines_of_context, tb_offset)\n",
            "  File \"/usr/local/lib/python3.10/dist-packages/IPython/core/ultratb.py\", line 248, in wrapped\n",
            "    return f(*args, **kwargs)\n",
            "  File \"/usr/local/lib/python3.10/dist-packages/IPython/core/ultratb.py\", line 281, in _fixed_getinnerframes\n",
            "    records = fix_frame_records_filenames(inspect.getinnerframes(etb, context))\n",
            "  File \"/usr/lib/python3.10/inspect.py\", line 1662, in getinnerframes\n",
            "    frameinfo = (tb.tb_frame,) + getframeinfo(tb, context)\n",
            "  File \"/usr/lib/python3.10/inspect.py\", line 1620, in getframeinfo\n",
            "    filename = getsourcefile(frame) or getfile(frame)\n",
            "  File \"/usr/lib/python3.10/inspect.py\", line 829, in getsourcefile\n",
            "    module = getmodule(object, filename)\n",
            "  File \"/usr/lib/python3.10/inspect.py\", line 861, in getmodule\n",
            "    file = getabsfile(object, _filename)\n",
            "  File \"/usr/lib/python3.10/inspect.py\", line 845, in getabsfile\n",
            "    return os.path.normcase(os.path.abspath(_filename))\n",
            "  File \"/usr/lib/python3.10/posixpath.py\", line 384, in abspath\n",
            "    cwd = os.getcwd()\n",
            "OSError: [Errno 107] Transport endpoint is not connected\n"
          ]
        }
      ]
    },
    {
      "cell_type": "code",
      "source": [],
      "metadata": {
        "id": "WEEeuOg2zs3u"
      },
      "execution_count": null,
      "outputs": []
    },
    {
      "cell_type": "code",
      "source": [],
      "metadata": {
        "id": "ogBXnORkztL6"
      },
      "execution_count": null,
      "outputs": []
    }
  ],
  "metadata": {
    "colab": {
      "provenance": [],
      "mount_file_id": "11xeS8SDCgzEuRTBIPpxS78I1-amS6T8k",
      "authorship_tag": "ABX9TyM/H1qZzsQpI10auQiRImqW",
      "include_colab_link": true
    },
    "kernelspec": {
      "display_name": "Python 3",
      "name": "python3"
    },
    "language_info": {
      "name": "python"
    }
  },
  "nbformat": 4,
  "nbformat_minor": 0
}